Workbook

Sheet Main
A1: CENTRUM LOTNICZE | C1: FLIGHT PLAN / PLAN LOTU
A2: DATE | B2: DEPARTURE | C2: DESTINATION | E2: A/C TYPE | G2: A/C IDENT | I2: PILOT | K2: INSTRUCTOR
A4: DEPARTURE CLEARANCE | D4: WEATHER & PERFORMANCE | H4: FREQUENCIES & TIMES
D5: WIND DIR [°] | H5: FREQ DEPARTURE
D6: WIND VEL [kt] | H6: FREQ DESTINATION
D7: IAS [kt] | H7: ETD
D8: TAS [kt] | F8: =IFERROR(IF(OR(F7="",L15=""),F7,F7*(1+0.02*L15/1000)),F7) -> 0 | H8: ATD
D9: TOTAL FUEL [L] | H9: ETA
D10: USEABLE [L] | H10: ATA
D11: FUEL FLOW [L/h] | H11: SR
D12: OAT [°C] | H12: SS
A14: WAYPOINT | B14: IDENT / FRQ | C14: MT [°] | D14: WCA [°] | E14: MH [°] | F14: DIST [NM] | G14: GS [kt] | H14: TIME [min] | I14: ETO [hh:mm] | J14: ATO [hh:mm] | K14: MIN ALT [ft] | L14: PLAN ALT [ft] | M14: Lat | N14: Lon
C15: =IF(A15="","",IFERROR(HYPERLINK("#"&"'Wszystkie punkty'!A"&MATCH(A15,'Wszystkie punkty'!$I:$I,0),"↗ Pokaż w bazie ('Wszystkie punkty')"),"(brak w bazie)")) | M15: =IFERROR(INDEX('Wszystkie punkty'!$F:$F,MATCH(A15,'Wszystkie punkty'!$I:$I,0)),"") | N15: =IFERROR(INDEX('Wszystkie punkty'!$G:$G,MATCH(A15,'Wszystkie punkty'!$I:$I,0)),"")
A16: ↓ | D16: =IFERROR(IF(OR(C16="",$F$6="",$F$8=""),"",ROUND(DEGREES(ASIN($F$6*SIN(RADIANS($F$5-C16))/$F$8)),0)),"") | E16: =IFERROR(IF(OR(C16="",D16=""),"",MOD(ROUND(C16+D16,0)+360,360)),"") | F16: =IFERROR(IF(OR(M15="",M17="",N15="",N17=""),"",ROUND(ACOS(MIN(1,SIN(RADIANS(M15))*SIN(RADIANS(M17))+COS(RADIANS(M15))*COS(RADIANS(M17))*COS(RADIANS(N17-N15))))*3440.065,1)),"") | G16: =IFERROR(IF(OR(C16="",$F$8=""),"",ROUND($F$8*COS(RADIANS(D16))-$F$6*COS(RADIANS($F$5-C16)),0)),"") | H16: =IFERROR(IF(OR(F16="",G16="",G16<=0),"",ROUND(F16/G16*60,0)),"") | I16: =IFERROR(IF(OR(H16="",$J$7=""),"",$J$7+H16/1440),"")
C17: =IF(A17="","",IFERROR(HYPERLINK("#"&"'Wszystkie punkty'!A"&MATCH(A17,'Wszystkie punkty'!$I:$I,0),"↗ Pokaż w bazie ('Wszystkie punkty')"),"(brak w bazie)")) | M17: =IFERROR(INDEX('Wszystkie punkty'!$F:$F,MATCH(A17,'Wszystkie punkty'!$I:$I,0)),"") | N17: =IFERROR(INDEX('Wszystkie punkty'!$G:$G,MATCH(A17,'Wszystkie punkty'!$I:$I,0)),"")
A18: ↓ | D18: =IFERROR(IF(OR(C18="",$F$6="",$F$8=""),"",ROUND(DEGREES(ASIN($F$6*SIN(RADIANS($F$5-C18))/$F$8)),0)),"") | E18: =IFERROR(IF(OR(C18="",D18=""),"",MOD(ROUND(C18+D18,0)+360,360)),"") | F18: =IFERROR(IF(OR(M17="",M19="",N17="",N19=""),"",ROUND(ACOS(MIN(1,SIN(RADIANS(M17))*SIN(RADIANS(M19))+COS(RADIANS(M17))*COS(RADIANS(M19))*COS(RADIANS(N19-N17))))*3440.065,1)),"") | G18: =IFERROR(IF(OR(C18="",$F$8=""),"",ROUND($F$8*COS(RADIANS(D18))-$F$6*COS(RADIANS($F$5-C18)),0)),"") | H18: =IFERROR(IF(OR(F18="",G18="",G18<=0),"",ROUND(F18/G18*60,0)),"") | I18: =IFERROR(IF(OR(H18="",I16=""),"",I16+H18/1440),"")
C19: =IF(A19="","",IFERROR(HYPERLINK("#"&"'Wszystkie punkty'!A"&MATCH(A19,'Wszystkie punkty'!$I:$I,0),"↗ Pokaż w bazie ('Wszystkie punkty')"),"(brak w bazie)")) | M19: =IFERROR(INDEX('Wszystkie punkty'!$F:$F,MATCH(A19,'Wszystkie punkty'!$I:$I,0)),"") | N19: =IFERROR(INDEX('Wszystkie punkty'!$G:$G,MATCH(A19,'Wszystkie punkty'!$I:$I,0)),"")
A20: ↓ | D20: =IFERROR(IF(OR(C20="",$F$6="",$F$8=""),"",ROUND(DEGREES(ASIN($F$6*SIN(RADIANS($F$5-C20))/$F$8)),0)),"") | E20: =IFERROR(IF(OR(C20="",D20=""),"",MOD(ROUND(C20+D20,0)+360,360)),"") | F20: =IFERROR(IF(OR(M19="",M21="",N19="",N21=""),"",ROUND(ACOS(MIN(1,SIN(RADIANS(M19))*SIN(RADIANS(M21))+COS(RADIANS(M19))*COS(RADIANS(M21))*COS(RADIANS(N21-N19))))*3440.065,1)),"") | G20: =IFERROR(IF(OR(C20="",$F$8=""),"",ROUND($F$8*COS(RADIANS(D20))-$F$6*COS(RADIANS($F$5-C20)),0)),"") | H20: =IFERROR(IF(OR(F20="",G20="",G20<=0),"",ROUND(F20/G20*60,0)),"") | I20: =IFERROR(IF(OR(H20="",I18=""),"",I18+H20/1440),"")
C21: =IF(A21="","",IFERROR(HYPERLINK("#"&"'Wszystkie punkty'!A"&MATCH(A21,'Wszystkie punkty'!$I:$I,0),"↗ Pokaż w bazie ('Wszystkie punkty')"),"(brak w bazie)")) | M21: =IFERROR(INDEX('Wszystkie punkty'!$F:$F,MATCH(A21,'Wszystkie punkty'!$I:$I,0)),"") | N21: =IFERROR(INDEX('Wszystkie punkty'!$G:$G,MATCH(A21,'Wszystkie punkty'!$I:$I,0)),"")
A22: ↓ | D22: =IFERROR(IF(OR(C22="",$F$6="",$F$8=""),"",ROUND(DEGREES(ASIN($F$6*SIN(RADIANS($F$5-C22))/$F$8)),0)),"") | E22: =IFERROR(IF(OR(C22="",D22=""),"",MOD(ROUND(C22+D22,0)+360,360)),"") | F22: =IFERROR(IF(OR(M21="",M23="",N21="",N23=""),"",ROUND(ACOS(MIN(1,SIN(RADIANS(M21))*SIN(RADIANS(M23))+COS(RADIANS(M21))*COS(RADIANS(M23))*COS(RADIANS(N23-N21))))*3440.065,1)),"") | G22: =IFERROR(IF(OR(C22="",$F$8=""),"",ROUND($F$8*COS(RADIANS(D22))-$F$6*COS(RADIANS($F$5-C22)),0)),"") | H22: =IFERROR(IF(OR(F22="",G22="",G22<=0),"",ROUND(F22/G22*60,0)),"") | I22: =IFERROR(IF(OR(H22="",I20=""),"",I20+H22/1440),"")
C23: =IF(A23="","",IFERROR(HYPERLINK("#"&"'Wszystkie punkty'!A"&MATCH(A23,'Wszystkie punkty'!$I:$I,0),"↗ Pokaż w bazie ('Wszystkie punkty')"),"(brak w bazie)")) | M23: =IFERROR(INDEX('Wszystkie punkty'!$F:$F,MATCH(A23,'Wszystkie punkty'!$I:$I,0)),"") | N23: =IFERROR(INDEX('Wszystkie punkty'!$G:$G,MATCH(A23,'Wszystkie punkty'!$I:$I,0)),"")
A24: ↓ | D24: =IFERROR(IF(OR(C24="",$F$6="",$F$8=""),"",ROUND(DEGREES(ASIN($F$6*SIN(RADIANS($F$5-C24))/$F$8)),0)),"") | E24: =IFERROR(IF(OR(C24="",D24=""),"",MOD(ROUND(C24+D24,0)+360,360)),"") | F24: =IFERROR(IF(OR(M23="",M25="",N23="",N25=""),"",ROUND(ACOS(MIN(1,SIN(RADIANS(M23))*SIN(RADIANS(M25))+COS(RADIANS(M23))*COS(RADIANS(M25))*COS(RADIANS(N25-N23))))*3440.065,1)),"") | G24: =IFERROR(IF(OR(C24="",$F$8=""),"",ROUND($F$8*COS(RADIANS(D24))-$F$6*COS(RADIANS($F$5-C24)),0)),"") | H24: =IFERROR(IF(OR(F24="",G24="",G24<=0),"",ROUND(F24/G24*60,0)),"") | I24: =IFERROR(IF(OR(H24="",I22=""),"",I22+H24/1440),"")
C25: =IF(A25="","",IFERROR(HYPERLINK("#"&"'Wszystkie punkty'!A"&MATCH(A25,'Wszystkie punkty'!$I:$I,0),"↗ Pokaż w bazie ('Wszystkie punkty')"),"(brak w bazie)")) | M25: =IFERROR(INDEX('Wszystkie punkty'!$F:$F,MATCH(A25,'Wszystkie punkty'!$I:$I,0)),"") | N25: =IFERROR(INDEX('Wszystkie punkty'!$G:$G,MATCH(A25,'Wszystkie punkty'!$I:$I,0)),"")
A26: ↓ | D26: =IFERROR(IF(OR(C26="",$F$6="",$F$8=""),"",ROUND(DEGREES(ASIN($F$6*SIN(RADIANS($F$5-C26))/$F$8)),0)),"") | E26: =IFERROR(IF(OR(C26="",D26=""),"",MOD(ROUND(C26+D26,0)+360,360)),"") | F26: =IFERROR(IF(OR(M25="",M27="",N25="",N27=""),"",ROUND(ACOS(MIN(1,SIN(RADIANS(M25))*SIN(RADIANS(M27))+COS(RADIANS(M25))*COS(RADIANS(M27))*COS(RADIANS(N27-N25))))*3440.065,1)),"") | G26: =IFERROR(IF(OR(C26="",$F$8=""),"",ROUND($F$8*COS(RADIANS(D26))-$F$6*COS(RADIANS($F$5-C26)),0)),"") | H26: =IFERROR(IF(OR(F26="",G26="",G26<=0),"",ROUND(F26/G26*60,0)),"") | I26: =IFERROR(IF(OR(H26="",I24=""),"",I24+H26/1440),"")
C27: =IF(A27="","",IFERROR(HYPERLINK("#"&"'Wszystkie punkty'!A"&MATCH(A27,'Wszystkie punkty'!$I:$I,0),"↗ Pokaż w bazie ('Wszystkie punkty')"),"(brak w bazie)")) | M27: =IFERROR(INDEX('Wszystkie punkty'!$F:$F,MATCH(A27,'Wszystkie punkty'!$I:$I,0)),"") | N27: =IFERROR(INDEX('Wszystkie punkty'!$G:$G,MATCH(A27,'Wszystkie punkty'!$I:$I,0)),"")
A28: ↓ | D28: =IFERROR(IF(OR(C28="",$F$6="",$F$8=""),"",ROUND(DEGREES(ASIN($F$6*SIN(RADIANS($F$5-C28))/$F$8)),0)),"") | E28: =IFERROR(IF(OR(C28="",D28=""),"",MOD(ROUND(C28+D28,0)+360,360)),"") | F28: =IFERROR(IF(OR(M27="",M29="",N27="",N29=""),"",ROUND(ACOS(MIN(1,SIN(RADIANS(M27))*SIN(RADIANS(M29))+COS(RADIANS(M27))*COS(RADIANS(M29))*COS(RADIANS(N29-N27))))*3440.065,1)),"") | G28: =IFERROR(IF(OR(C28="",$F$8=""),"",ROUND($F$8*COS(RADIANS(D28))-$F$6*COS(RADIANS($F$5-C28)),0)),"") | H28: =IFERROR(IF(OR(F28="",G28="",G28<=0),"",ROUND(F28/G28*60,0)),"") | I28: =IFERROR(IF(OR(H28="",I26=""),"",I26+H28/1440),"")
C29: =IF(A29="","",IFERROR(HYPERLINK("#"&"'Wszystkie punkty'!A"&MATCH(A29,'Wszystkie punkty'!$I:$I,0),"↗ Pokaż w bazie ('Wszystkie punkty')"),"(brak w bazie)")) | M29: =IFERROR(INDEX('Wszystkie punkty'!$F:$F,MATCH(A29,'Wszystkie punkty'!$I:$I,0)),"") | N29: =IFERROR(INDEX('Wszystkie punkty'!$G:$G,MATCH(A29,'Wszystkie punkty'!$I:$I,0)),"")
A30: ↓ | D30: =IFERROR(IF(OR(C30="",$F$6="",$F$8=""),"",ROUND(DEGREES(ASIN($F$6*SIN(RADIANS($F$5-C30))/$F$8)),0)),"") | E30: =IFERROR(IF(OR(C30="",D30=""),"",MOD(ROUND(C30+D30,0)+360,360)),"") | F30: =IFERROR(IF(OR(M29="",M31="",N29="",N31=""),"",ROUND(ACOS(MIN(1,SIN(RADIANS(M29))*SIN(RADIANS(M31))+COS(RADIANS(M29))*COS(RADIANS(M31))*COS(RADIANS(N31-N29))))*3440.065,1)),"") | G30: =IFERROR(IF(OR(C30="",$F$8=""),"",ROUND($F$8*COS(RADIANS(D30))-$F$6*COS(RADIANS($F$5-C30)),0)),"") | H30: =IFERROR(IF(OR(F30="",G30="",G30<=0),"",ROUND(F30/G30*60,0)),"") | I30: =IFERROR(IF(OR(H30="",I28=""),"",I28+H30/1440),"")
C31: =IF(A31="","",IFERROR(HYPERLINK("#"&"'Wszystkie punkty'!A"&MATCH(A31,'Wszystkie punkty'!$I:$I,0),"↗ Pokaż w bazie ('Wszystkie punkty')"),"(brak w bazie)")) | M31: =IFERROR(INDEX('Wszystkie punkty'!$F:$F,MATCH(A31,'Wszystkie punkty'!$I:$I,0)),"") | N31: =IFERROR(INDEX('Wszystkie punkty'!$G:$G,MATCH(A31,'Wszystkie punkty'!$I:$I,0)),"")
A32: ↓ | D32: =IFERROR(IF(OR(C32="",$F$6="",$F$8=""),"",ROUND(DEGREES(ASIN($F$6*SIN(RADIANS($F$5-C32))/$F$8)),0)),"") | E32: =IFERROR(IF(OR(C32="",D32=""),"",MOD(ROUND(C32+D32,0)+360,360)),"") | F32: =IFERROR(IF(OR(M31="",M33="",N31="",N33=""),"",ROUND(ACOS(MIN(1,SIN(RADIANS(M31))*SIN(RADIANS(M33))+COS(RADIANS(M31))*COS(RADIANS(M33))*COS(RADIANS(N33-N31))))*3440.065,1)),"") | G32: =IFERROR(IF(OR(C32="",$F$8=""),"",ROUND($F$8*COS(RADIANS(D32))-$F$6*COS(RADIANS($F$5-C32)),0)),"") | H32: =IFERROR(IF(OR(F32="",G32="",G32<=0),"",ROUND(F32/G32*60,0)),"") | I32: =IFERROR(IF(OR(H32="",I30=""),"",I30+H32/1440),"")
C33: =IF(A33="","",IFERROR(HYPERLINK("#"&"'Wszystkie punkty'!A"&MATCH(A33,'Wszystkie punkty'!$I:$I,0),"↗ Pokaż w bazie ('Wszystkie punkty')"),"(brak w bazie)")) | M33: =IFERROR(INDEX('Wszystkie punkty'!$F:$F,MATCH(A33,'Wszystkie punkty'!$I:$I,0)),"") | N33: =IFERROR(INDEX('Wszystkie punkty'!$G:$G,MATCH(A33,'Wszystkie punkty'!$I:$I,0)),"")
A34: TOTALS / RAZEM | F34: =SUM(F16:F32) -> 0 | H34: =SUM(H16:H32) -> 0 | I34: =IFERROR(LOOKUP(2,1/(I16:I32<>""),I16:I32),"")
A35: FUEL PLANNING / PALIWO | G35: ALTERNATE / LOTNISKO ZAPASOWE
A36: Trip fuel [L] | D36: =IFERROR(ROUND(H34/60*$F$11,1),"") -> 0 | G36: Alternate field:
A37: Reserve (30 min) [L] | D37: =IFERROR(ROUND(30/60*$F$11,1),"") -> 0 | G37: Distance [NM]:
A38: Block fuel needed [L] | D38: =IFERROR(D36+D37,"") -> 0 | G38: Extra time [min]:
A39: ARRIVAL CLEARANCE / NOTES / NOTAM
A42: PILOT SIGNATURE | G42: INSTRUCTOR SIGNATURE

Sheet Sample
A1: CENTRUM LOTNICZE | C1: FLIGHT PLAN / PLAN LOTU
A2: DATE | B2: DEPARTURE | C2: DESTINATION | E2: A/C TYPE | G2: A/C IDENT | I2: PILOT | K2: INSTRUCTOR
A4: DEPARTURE CLEARANCE | D4: WEATHER & PERFORMANCE | H4: FREQUENCIES & TIMES
D5: WIND DIR [°] | F5: 10 | H5: FREQ DEPARTURE
D6: WIND VEL [kt] | F6: 10 | H6: FREQ DESTINATION
D7: IAS [kt] | F7: 75 | H7: ETD
D8: TAS [kt] | F8: =IFERROR(IF(OR(F7="",L15=""),F7,F7*(1+0.02*L15/1000)),F7) -> 75 | H8: ATD
D9: TOTAL FUEL [L] | H9: ETA
D10: USEABLE [L] | H10: ATA
D11: FUEL FLOW [L/h] | H11: SR
D12: OAT [°C] | H12: SS
A14: WAYPOINT | B14: IDENT / FRQ | C14: MT [°] | D14: WCA [°] | E14: MH [°] | F14: DIST [NM] | G14: GS [kt] | H14: TIME [min] | I14: ETO [hh:mm] | J14: ATO [hh:mm] | K14: MIN ALT [ft] | L14: PLAN ALT [ft] | M14: Lat | N14: Lon
A15: EPBC ARP | C15: =IF(A15="","",IFERROR(HYPERLINK("#"&"'Wszystkie punkty'!A"&MATCH(A15,'[1]Wszystkie punkty'!$I:$I,0),"↗ Pokaż w bazie ('Wszystkie punkty')"),"(brak w bazie)")) -> ↗ Pokaż w bazie ('Wszystkie punkty') | M15: =IFERROR(INDEX('[1]Wszystkie punkty'!$F:$F,MATCH(A15,'[1]Wszystkie punkty'!$I:$I,0)),"") -> 52.269194 | N15: =IFERROR(INDEX('[1]Wszystkie punkty'!$G:$G,MATCH(A15,'[1]Wszystkie punkty'!$I:$I,0)),"") -> 20.907222
A16: ↓ | D16: =IFERROR(IF(OR(C16="",$F$6="",$F$8=""),"",ROUND(DEGREES(ASIN($F$6*SIN(RADIANS($F$5-C16))/$F$8)),0)),"") | E16: =IFERROR(IF(OR(C16="",D16=""),"",MOD(ROUND(C16+D16,0)+360,360)),"") | F16: =IFERROR(IF(OR(M15="",M17="",N15="",N17=""),"",ROUND(ACOS(MIN(1,SIN(RADIANS(M15))*SIN(RADIANS(M17))+COS(RADIANS(M15))*COS(RADIANS(M17))*COS(RADIANS(N17-N15))))*3440.065,1)),"") -> 4 | G16: =IFERROR(IF(OR(C16="",$F$8=""),"",ROUND($F$8*COS(RADIANS(D16))-$F$6*COS(RADIANS($F$5-C16)),0)),"") | H16: =IFERROR(IF(OR(F16="",G16="",G16<=0),"",ROUND(F16/G16*60,0)),"") | I16: =IFERROR(IF(OR(H16="",$J$7=""),"",$J$7+H16/1440),"")
A17: ZULU/EPBC | C17: =IF(A17="","",IFERROR(HYPERLINK("#"&"'Wszystkie punkty'!A"&MATCH(A17,'[1]Wszystkie punkty'!$I:$I,0),"↗ Pokaż w bazie ('Wszystkie punkty')"),"(brak w bazie)")) -> ↗ Pokaż w bazie ('Wszystkie punkty') | M17: =IFERROR(INDEX('[1]Wszystkie punkty'!$F:$F,MATCH(A17,'[1]Wszystkie punkty'!$I:$I,0)),"") -> 52.29028 | N17: =IFERROR(INDEX('[1]Wszystkie punkty'!$G:$G,MATCH(A17,'[1]Wszystkie punkty'!$I:$I,0)),"") -> 21.01083
A18: ↓ | D18: =IFERROR(IF(OR(C18="",$F$6="",$F$8=""),"",ROUND(DEGREES(ASIN($F$6*SIN(RADIANS($F$5-C18))/$F$8)),0)),"") | E18: =IFERROR(IF(OR(C18="",D18=""),"",MOD(ROUND(C18+D18,0)+360,360)),"") | F18: =IFERROR(IF(OR(M17="",M19="",N17="",N19=""),"",ROUND(ACOS(MIN(1,SIN(RADIANS(M17))*SIN(RADIANS(M19))+COS(RADIANS(M17))*COS(RADIANS(M19))*COS(RADIANS(N19-N17))))*3440.065,1)),"") -> 12.3 | G18: =IFERROR(IF(OR(C18="",$F$8=""),"",ROUND($F$8*COS(RADIANS(D18))-$F$6*COS(RADIANS($F$5-C18)),0)),"") | H18: =IFERROR(IF(OR(F18="",G18="",G18<=0),"",ROUND(F18/G18*60,0)),"") | I18: =IFERROR(IF(OR(H18="",I16=""),"",I16+H18/1440),"")
A19: CHARLIE/EPNC | C19: =IF(A19="","",IFERROR(HYPERLINK("#"&"'Wszystkie punkty'!A"&MATCH(A19,'[1]Wszystkie punkty'!$I:$I,0),"↗ Pokaż w bazie ('Wszystkie punkty')"),"(brak w bazie)")) -> ↗ Pokaż w bazie ('Wszystkie punkty') | M19: =IFERROR(INDEX('[1]Wszystkie punkty'!$F:$F,MATCH(A19,'[1]Wszystkie punkty'!$I:$I,0)),"") -> 52.48861 | N19: =IFERROR(INDEX('[1]Wszystkie punkty'!$G:$G,MATCH(A19,'[1]Wszystkie punkty'!$I:$I,0)),"") -> 20.92361
A20: ↓ | D20: =IFERROR(IF(OR(C20="",$F$6="",$F$8=""),"",ROUND(DEGREES(ASIN($F$6*SIN(RADIANS($F$5-C20))/$F$8)),0)),"") | E20: =IFERROR(IF(OR(C20="",D20=""),"",MOD(ROUND(C20+D20,0)+360,360)),"") | F20: =IFERROR(IF(OR(M19="",M21="",N19="",N21=""),"",ROUND(ACOS(MIN(1,SIN(RADIANS(M19))*SIN(RADIANS(M21))+COS(RADIANS(M19))*COS(RADIANS(M21))*COS(RADIANS(N21-N19))))*3440.065,1)),"") -> 5.5 | G20: =IFERROR(IF(OR(C20="",$F$8=""),"",ROUND($F$8*COS(RADIANS(D20))-$F$6*COS(RADIANS($F$5-C20)),0)),"") | H20: =IFERROR(IF(OR(F20="",G20="",G20<=0),"",ROUND(F20/G20*60,0)),"") | I20: =IFERROR(IF(OR(H20="",I18=""),"",I18+H20/1440),"")
A21: EPNC ARP | C21: =IF(A21="","",IFERROR(HYPERLINK("#"&"'Wszystkie punkty'!A"&MATCH(A21,'[1]Wszystkie punkty'!$I:$I,0),"↗ Pokaż w bazie ('Wszystkie punkty')"),"(brak w bazie)")) -> ↗ Pokaż w bazie ('Wszystkie punkty') | M21: =IFERROR(INDEX('[1]Wszystkie punkty'!$F:$F,MATCH(A21,'[1]Wszystkie punkty'!$I:$I,0)),"") -> 52.574 | N21: =IFERROR(INDEX('[1]Wszystkie punkty'!$G:$G,MATCH(A21,'[1]Wszystkie punkty'!$I:$I,0)),"") -> 20.871917
A22: ↓ | D22: =IFERROR(IF(OR(C22="",$F$6="",$F$8=""),"",ROUND(DEGREES(ASIN($F$6*SIN(RADIANS($F$5-C22))/$F$8)),0)),"") | E22: =IFERROR(IF(OR(C22="",D22=""),"",MOD(ROUND(C22+D22,0)+360,360)),"") | F22: =IFERROR(IF(OR(M21="",M23="",N21="",N23=""),"",ROUND(ACOS(MIN(1,SIN(RADIANS(M21))*SIN(RADIANS(M23))+COS(RADIANS(M21))*COS(RADIANS(M23))*COS(RADIANS(N23-N21))))*3440.065,1)),"") | G22: =IFERROR(IF(OR(C22="",$F$8=""),"",ROUND($F$8*COS(RADIANS(D22))-$F$6*COS(RADIANS($F$5-C22)),0)),"") | H22: =IFERROR(IF(OR(F22="",G22="",G22<=0),"",ROUND(F22/G22*60,0)),"") | I22: =IFERROR(IF(OR(H22="",I20=""),"",I20+H22/1440),"")
C23: =IF(A23="","",IFERROR(HYPERLINK("#"&"'Wszystkie punkty'!A"&MATCH(A23,'[1]Wszystkie punkty'!$I:$I,0),"↗ Pokaż w bazie ('Wszystkie punkty')"),"(brak w bazie)")) | M23: =IFERROR(INDEX('[1]Wszystkie punkty'!$F:$F,MATCH(A23,'[1]Wszystkie punkty'!$I:$I,0)),"") | N23: =IFERROR(INDEX('[1]Wszystkie punkty'!$G:$G,MATCH(A23,'[1]Wszystkie punkty'!$I:$I,0)),"")
A24: ↓ | D24: =IFERROR(IF(OR(C24="",$F$6="",$F$8=""),"",ROUND(DEGREES(ASIN($F$6*SIN(RADIANS($F$5-C24))/$F$8)),0)),"") | E24: =IFERROR(IF(OR(C24="",D24=""),"",MOD(ROUND(C24+D24,0)+360,360)),"") | F24: =IFERROR(IF(OR(M23="",M25="",N23="",N25=""),"",ROUND(ACOS(MIN(1,SIN(RADIANS(M23))*SIN(RADIANS(M25))+COS(RADIANS(M23))*COS(RADIANS(M25))*COS(RADIANS(N25-N23))))*3440.065,1)),"") | G24: =IFERROR(IF(OR(C24="",$F$8=""),"",ROUND($F$8*COS(RADIANS(D24))-$F$6*COS(RADIANS($F$5-C24)),0)),"") | H24: =IFERROR(IF(OR(F24="",G24="",G24<=0),"",ROUND(F24/G24*60,0)),"") | I24: =IFERROR(IF(OR(H24="",I22=""),"",I22+H24/1440),"")
C25: =IF(A25="","",IFERROR(HYPERLINK("#"&"'Wszystkie punkty'!A"&MATCH(A25,'[1]Wszystkie punkty'!$I:$I,0),"↗ Pokaż w bazie ('Wszystkie punkty')"),"(brak w bazie)")) | M25: =IFERROR(INDEX('[1]Wszystkie punkty'!$F:$F,MATCH(A25,'[1]Wszystkie punkty'!$I:$I,0)),"") | N25: =IFERROR(INDEX('[1]Wszystkie punkty'!$G:$G,MATCH(A25,'[1]Wszystkie punkty'!$I:$I,0)),"")
A26: ↓ | D26: =IFERROR(IF(OR(C26="",$F$6="",$F$8=""),"",ROUND(DEGREES(ASIN($F$6*SIN(RADIANS($F$5-C26))/$F$8)),0)),"") | E26: =IFERROR(IF(OR(C26="",D26=""),"",MOD(ROUND(C26+D26,0)+360,360)),"") | F26: =IFERROR(IF(OR(M25="",M27="",N25="",N27=""),"",ROUND(ACOS(MIN(1,SIN(RADIANS(M25))*SIN(RADIANS(M27))+COS(RADIANS(M25))*COS(RADIANS(M27))*COS(RADIANS(N27-N25))))*3440.065,1)),"") | G26: =IFERROR(IF(OR(C26="",$F$8=""),"",ROUND($F$8*COS(RADIANS(D26))-$F$6*COS(RADIANS($F$5-C26)),0)),"") | H26: =IFERROR(IF(OR(F26="",G26="",G26<=0),"",ROUND(F26/G26*60,0)),"") | I26: =IFERROR(IF(OR(H26="",I24=""),"",I24+H26/1440),"")
C27: =IF(A27="","",IFERROR(HYPERLINK("#"&"'Wszystkie punkty'!A"&MATCH(A27,'[1]Wszystkie punkty'!$I:$I,0),"↗ Pokaż w bazie ('Wszystkie punkty')"),"(brak w bazie)")) | M27: =IFERROR(INDEX('[1]Wszystkie punkty'!$F:$F,MATCH(A27,'[1]Wszystkie punkty'!$I:$I,0)),"") | N27: =IFERROR(INDEX('[1]Wszystkie punkty'!$G:$G,MATCH(A27,'[1]Wszystkie punkty'!$I:$I,0)),"")
A28: ↓ | D28: =IFERROR(IF(OR(C28="",$F$6="",$F$8=""),"",ROUND(DEGREES(ASIN($F$6*SIN(RADIANS($F$5-C28))/$F$8)),0)),"") | E28: =IFERROR(IF(OR(C28="",D28=""),"",MOD(ROUND(C28+D28,0)+360,360)),"") | F28: =IFERROR(IF(OR(M27="",M29="",N27="",N29=""),"",ROUND(ACOS(MIN(1,SIN(RADIANS(M27))*SIN(RADIANS(M29))+COS(RADIANS(M27))*COS(RADIANS(M29))*COS(RADIANS(N29-N27))))*3440.065,1)),"") | G28: =IFERROR(IF(OR(C28="",$F$8=""),"",ROUND($F$8*COS(RADIANS(D28))-$F$6*COS(RADIANS($F$5-C28)),0)),"") | H28: =IFERROR(IF(OR(F28="",G28="",G28<=0),"",ROUND(F28/G28*60,0)),"") | I28: =IFERROR(IF(OR(H28="",I26=""),"",I26+H28/1440),"")
C29: =IF(A29="","",IFERROR(HYPERLINK("#"&"'Wszystkie punkty'!A"&MATCH(A29,'[1]Wszystkie punkty'!$I:$I,0),"↗ Pokaż w bazie ('Wszystkie punkty')"),"(brak w bazie)")) | M29: =IFERROR(INDEX('[1]Wszystkie punkty'!$F:$F,MATCH(A29,'[1]Wszystkie punkty'!$I:$I,0)),"") | N29: =IFERROR(INDEX('[1]Wszystkie punkty'!$G:$G,MATCH(A29,'[1]Wszystkie punkty'!$I:$I,0)),"")
A30: ↓ | D30: =IFERROR(IF(OR(C30="",$F$6="",$F$8=""),"",ROUND(DEGREES(ASIN($F$6*SIN(RADIANS($F$5-C30))/$F$8)),0)),"") | E30: =IFERROR(IF(OR(C30="",D30=""),"",MOD(ROUND(C30+D30,0)+360,360)),"") | F30: =IFERROR(IF(OR(M29="",M31="",N29="",N31=""),"",ROUND(ACOS(MIN(1,SIN(RADIANS(M29))*SIN(RADIANS(M31))+COS(RADIANS(M29))*COS(RADIANS(M31))*COS(RADIANS(N31-N29))))*3440.065,1)),"") | G30: =IFERROR(IF(OR(C30="",$F$8=""),"",ROUND($F$8*COS(RADIANS(D30))-$F$6*COS(RADIANS($F$5-C30)),0)),"") | H30: =IFERROR(IF(OR(F30="",G30="",G30<=0),"",ROUND(F30/G30*60,0)),"") | I30: =IFERROR(IF(OR(H30="",I28=""),"",I28+H30/1440),"")
C31: =IF(A31="","",IFERROR(HYPERLINK("#"&"'Wszystkie punkty'!A"&MATCH(A31,'[1]Wszystkie punkty'!$I:$I,0),"↗ Pokaż w bazie ('Wszystkie punkty')"),"(brak w bazie)")) | M31: =IFERROR(INDEX('[1]Wszystkie punkty'!$F:$F,MATCH(A31,'[1]Wszystkie punkty'!$I:$I,0)),"") | N31: =IFERROR(INDEX('[1]Wszystkie punkty'!$G:$G,MATCH(A31,'[1]Wszystkie punkty'!$I:$I,0)),"")
A32: ↓ | D32: =IFERROR(IF(OR(C32="",$F$6="",$F$8=""),"",ROUND(DEGREES(ASIN($F$6*SIN(RADIANS($F$5-C32))/$F$8)),0)),"") | E32: =IFERROR(IF(OR(C32="",D32=""),"",MOD(ROUND(C32+D32,0)+360,360)),"") | F32: =IFERROR(IF(OR(M31="",M33="",N31="",N33=""),"",ROUND(ACOS(MIN(1,SIN(RADIANS(M31))*SIN(RADIANS(M33))+COS(RADIANS(M31))*COS(RADIANS(M33))*COS(RADIANS(N33-N31))))*3440.065,1)),"") | G32: =IFERROR(IF(OR(C32="",$F$8=""),"",ROUND($F$8*COS(RADIANS(D32))-$F$6*COS(RADIANS($F$5-C32)),0)),"") | H32: =IFERROR(IF(OR(F32="",G32="",G32<=0),"",ROUND(F32/G32*60,0)),"") | I32: =IFERROR(IF(OR(H32="",I30=""),"",I30+H32/1440),"")
C33: =IF(A33="","",IFERROR(HYPERLINK("#"&"'Wszystkie punkty'!A"&MATCH(A33,'[1]Wszystkie punkty'!$I:$I,0),"↗ Pokaż w bazie ('Wszystkie punkty')"),"(brak w bazie)")) | M33: =IFERROR(INDEX('[1]Wszystkie punkty'!$F:$F,MATCH(A33,'[1]Wszystkie punkty'!$I:$I,0)),"") | N33: =IFERROR(INDEX('[1]Wszystkie punkty'!$G:$G,MATCH(A33,'[1]Wszystkie punkty'!$I:$I,0)),"")
A34: TOTALS / RAZEM | F34: =SUM(F16:F32) -> 21.8 | H34: =SUM(H16:H32) -> 0 | I34: =IFERROR(LOOKUP(2,1/(I16:I32<>""),I16:I32),"")
A35: FUEL PLANNING / PALIWO | G35: ALTERNATE / LOTNISKO ZAPASOWE
A36: Trip fuel [L] | D36: =IFERROR(ROUND(H34/60*$F$11,1),"") -> 0 | G36: Alternate field:
A37: Reserve (30 min) [L] | D37: =IFERROR(ROUND(30/60*$F$11,1),"") -> 0 | G37: Distance [NM]:
A38: Block fuel needed [L] | D38: =IFERROR(D36+D37,"") -> 0 | G38: Extra time [min]:
A39: ARRIVAL CLEARANCE / NOTES / NOTAM
A42: PILOT SIGNATURE | G42: INSTRUCTOR SIGNATURE

Sheet README
A2: FLIGHT PLAN — Centrum Lotnicze
A3: Naw-log z auto-obliczeniami trójkąta wiatru (v4 — protected)
A5: OCHRONA ARKUSZA
A6: • Edytować można TYLKO żółte komórki (input)
A7: • Pola wyszarzane (gray dead zone) i niebieskie (calc) są zablokowane
A8: • Aby odblokować arkusz: Review → Unprotect Sheet (bez hasła)
A10: UKŁAD TABELI TRASY
A11: • Wiersze WAYPOINT (jasnoniebieski pasek): nazwa, frq, min/plan altitude — środek (C..J) zmergowany jako "dead zone"
A12: • Wiersze LEG między waypointami (↓): MT, WCA, MH, DIST, GS, TIME, ETO, ATO
A13: • Logika: kurs/dystans dotyczy ODCINKA pomiędzy dwoma waypointami
A15: KOLORY
A16: • Żółte = pola edytowalne (input)
... A39: • Lotniska z "Przegląd lotnisk" zostały dopisane do "Wszystkie punkty" (jasnopomarańczowe)

Sheet Wszystkie punkty
A1: Punkty meldunkowe VFR w Polsce — kompletna baza
A3: ICAO | B3: Lotnisko / Lądowisko | C3: Typ przestrzeni | D3: AD Ref | E3: Punkt | F3: Lat (decimal) | G3: Lon (decimal) | H3: Opis / Landmark | I3: Display (lookup)
A4: EPBA | B4: ALEKSANDROWICE k/Bielska-Białej | C4: ATZ | D4: AD 4 | E4: ALFA | F4: 49.84833 | G4: 19.03028 | H4: Skrzyż. drogi Bielsko-Biała-Katowice z obw. wschodnią | I4: ALFA/EPBA
A5: EPBA | B5: ALEKSANDROWICE k/Bielska-Białej | C5: ATZ | D5: AD 4 | E5: BRAVO | F5: 49.80528 | G5: 18.89139 | H5: Świętoszówka - wiadukt nad szosą Bielsko-Cieszyn | I5: BRAVO/EPBA
A6: EPBA | B6: ALEKSANDROWICE k/Bielska-Białej | C6: ATZ | D6: AD 4 | E6: CHARLIE | F6: 49.78583 | G6: 19.06778 | H6: Wyjazd z drogi B-B - Szczyrk na obwodnicę wschodnią | I6: CHARLIE/EPBA
A7: EPBC | B7: WARSZAWA - BABICE | C7: ATZ (AFIS) | D7: AD 4 | E7: ALFA | F7: 52.06333 | G7: 20.74333 | H7: Magazyn w m. Siestrzeń | I7: ALFA/EPBC
A8: EPBC | B8: WARSZAWA - BABICE | C8: ATZ (AFIS) | D8: AD 4 | E8: BRAVO | F8: 52.18417 | G8: 20.61389 | H8: Fabryka w m. Błonie | I8: BRAVO/EPBC
A9: EPBC | B9: WARSZAWA - BABICE | C9: ATZ (AFIS) | D9: AD 4 | E9: DELTA | F9: 52.34333 | G9: 21.22778 | H9: Miejscowość Wołomin | I9: DELTA/EPBC
A10: EPBC | B10: WARSZAWA - BABICE | C10: ATZ (AFIS) | D10: AD 4 | E10: ECHO | F10: 52.18167 | G10: 20.98611 | H10: Skrzyżowanie ul. Marynarskiej i trasy S79 | I10: ECHO/EPBC
A11: EPBC | B11: WARSZAWA - BABICE | C11: ATZ (AFIS) | D11: AD 4 | E11: FOXTROT | F11: 52.26083 | G11: 20.73556 | H11: Skrzyżowanie dróg 1 km na N od Borzęcin Duży | I11: FOXTROT/EPBC
A12: EPBC | B12: WARSZAWA - BABICE | C12: ATZ (AFIS) | D12: AD 4 | E12: GOLF | F12: 51.99083 | G12: 21.23472 | H12: Most drogowy w m. Góra Kalwaria | I12: GOLF/EPBC
A13: EPBC | B13: WARSZAWA - BABICE | C13: ATZ (AFIS) | D13: AD 4 | E13: JULIETT | F13: 52.37778 | G13: 20.91667 | H13: M. Jabłonna | I13: JULIETT/EPBC
A14: EPBC | B14: WARSZAWA - BABICE | C14: ATZ (AFIS) | D14: AD 4 | E14: KILO | F14: 52.09139 | G14: 21.2375 | H14: Oczyszczalnia w m. Karczew | I14: KILO/EPBC
A15: EPBC | B15: WARSZAWA - BABICE | C15: ATZ (AFIS) | D15: AD 4 | E15: LUQIQ | F15: 52.34444 | G15: 20.92083 | H15: Zadrzewiona wyspa na Wiśle | I15: LUQIQ/EPBC
... A400: EPZR | B400: ŻAR k/Żywca | C400: ATZ | D400: AD 4 | E400: ARP | F400: 49.770972 | G400: 19.218139 | H400: Aerodrome Reference Point — ŻAR k/Żywca | I400: EPZR ARP

Sheet DMS (format AIP)
A1: Punkty VFR — współrzędne DMS (format AIP: ddmmssN / dddmmssE)
A3: ICAO | B3: Lotnisko | C3: Punkt | D3: Lat DMS | E3: Lon DMS | F3: Opis
A4: EPBA | B4: ALEKSANDROWICE k/Bielska-Białej | C4: ALFA | D4: 495054N | E4: 0190149E | F4: Skrzyż. drogi Bielsko-Biała-Katowice z obw. wschodnią
A5: EPBA | B5: ALEKSANDROWICE k/Bielska-Białej | C5: BRAVO | D5: 494819N | E5: 0185329E | F5: Świętoszówka - wiadukt nad szosą Bielsko-Cieszyn
A6: EPBA | B6: ALEKSANDROWICE k/Bielska-Białej | C6: CHARLIE | D6: 494709N | E6: 0190404E | F6: Wyjazd z drogi B-B - Szczyrk na obwodnicę wschodnią
A7: EPBC | B7: WARSZAWA - BABICE | C7: ALFA | D7: 520348N | E7: 0204436E | F7: Magazyn w m. Siestrzeń
A8: EPBC | B8: WARSZAWA - BABICE | C8: BRAVO | D8: 521103N | E8: 0203650E | F8: Fabryka w m. Błonie
A9: EPBC | B9: WARSZAWA - BABICE | C9: DELTA | D9: 522036N | E9: 0211340E | F9: Miejscowość Wołomin
A10: EPBC | B10: WARSZAWA - BABICE | C10: ECHO | D10: 521054N | E10: 0205910E | F10: Skrzyżowanie ul. Marynarskiej i trasy S79
A11: EPBC | B11: WARSZAWA - BABICE | C11: FOXTROT | D11: 521539N | E11: 0204408E | F11: Skrzyżowanie dróg 1 km na N od Borzęcin Duży
A12: EPBC | B12: WARSZAWA - BABICE | C12: GOLF | D12: 515927N | E12: 0211405E | F12: Most drogowy w m. Góra Kalwaria
A13: EPBC | B13: WARSZAWA - BABICE | C13: JULIETT | D13: 522240N | E13: 0205500E | F13: M. Jabłonna
A14: EPBC | B14: WARSZAWA - BABICE | C14: KILO | D14: 520529N | E14: 0211415E | F14: Oczyszczalnia w m. Karczew
... A345: EPZR | B345: ŻAR k/Żywca | C345: WHISKEY | D345: 494542N | E345: 0190527E | F345: Wilkowice - skrzyż. w centrum

Sheet Przegląd lotnisk
A1: Przegląd lotnisk z punktami VFR
A3: ICAO | B3: Lotnisko / Lądowisko | C3: Typ | D3: AD Ref | E3: Lat ARP | F3: Lon ARP | G3: Punktów VFR
A4: EPBA | B4: ALEKSANDROWICE k/Bielska-Białej | C4: ATZ | D4: AD 4 | E4: 49.805 | F4: 19.002028 | G4: 3
A5: EPBC | B5: WARSZAWA - BABICE | C5: ATZ (AFIS) | D5: AD 4 | E5: 52.269194 | F5: 20.907222 | G5: 14
A6: EPBK | B6: BIAŁYSTOK KRYWLANY | C6: ATZ | D6: AD 4 | E6: 53.10225 | F6: 23.171056 | G6: 6
A7: EPBY | B7: BYDGOSZCZ | C7: CTR/ATZ | D7: AD 2 | E7: 53.096667 | F7: 17.977778 | G7: 10
A8: EPCD | B8: DEPUŁTYCZE KRÓLEWSKIE | C8: ATZ | D8: AD 4 | E8: 51.082722 | F8: 23.43775 | G8: 3
A9: EPGD | B9: GDAŃSK im. Lecha Wałęsy | C9: CTR/TMA | D9: AD 2 | E9: 54.3775 | F9: 18.466111 | G9: 7
A10: EPGI | B10: LISIE KĄTY k/Grudziądza | C10: ATZ | D10: AD 4 | E10: 53.524417 | F10: 18.849472 | G10: 5
A11: EPGL | B11: GLIWICE | C11: ATZ | D11: AD 4 | E11: 50.269944 | F11: 18.672389 | G11: 7
A12: EPIN | B12: INOWROCŁAW | C12: ATZ | D12: AD 4 | E12: 52.806278 | F12: 18.284861 | G12: 8
A13: EPJG | B13: JELENIA GÓRA | C13: ATZ | D13: AD 4 | E13: 50.89875 | F13: 15.785167 | G13: 6
A14: EPJS | B14: JEŻÓW SUDECKI k/Jeleniej Góry | C14: ATZ | D14: AD 4 | E14: 50.944028 | F14: 15.766528 | G14: 6
A15: EPKA | B15: MASŁÓW k/Kielc | C15: ATZ | D15: AD 4 | E15: 50.896861 | F15: 20.731361 | G15: 5
... A58: EPZR | B58: ŻAR k/Żywca | C58: ATZ | D58: AD 4 | E58: 49.770972 | F58: 19.218139 | G58: 6
A59: RAZEM | B59: 55 lotnisk | G59: =SUM(G4:G58) -> 342

Sheet Bez punktów VFR
A1: Lotniska AD4 w AIP VFR — bez opublikowanych punktów nawigacyjnych
A3: ICAO | B3: Nazwa | C3: Uwagi
A4: EPBO | B4: BORSK | C4: Brak punktów w AIP VFR (wg pilothub.pl)
A5: EPEL | B5: ELBLĄG | C5: Brak punktów w AIP VFR (wg pilothub.pl)
A6: EPGY | B6: GRĄDY | C6: Brak punktów w AIP VFR (wg pilothub.pl)
A7: EPKG | B7: BAGICZ k/Kołobrzegu | C7: Brak punktów w AIP VFR (wg pilothub.pl)
A8: EPKI | B8: KIKITY | C8: Brak punktów w AIP VFR (wg pilothub.pl)
A9: EPLR | B9: RADAWIEC k/Lublina | C9: Brak punktów w AIP VFR (wg pilothub.pl)
A10: EPLU | B10: LUBIN | C10: Brak punktów w AIP VFR (wg pilothub.pl)
A11: EPMX | B11: MILEWO | C11: Brak punktów w AIP VFR (wg pilothub.pl)
A12: EPMY | B12: MYŚLIBÓRZ-GIŻYN | C12: Brak punktów w AIP VFR (wg pilothub.pl)
A13: EPNL | B13: ŁOSOSINA DOLNA k/Nowego Sącza | C13: Brak punktów w AIP VFR (wg pilothub.pl)
A14: EPPZ | B14: PRZASNYSZ | C14: Brak punktów w AIP VFR (wg pilothub.pl)
... A16: EPSL | B16: ŚWIDNIK k/LUBLINA | C16: Brak punktów w AIP VFR (wg pilothub.pl)

Sheet ENR Granica FIR
A1: Punkty meldowania VFR na granicy FIR Warszawa (EPWW) — AIP VFR ENR 2.1.1
A2: ⚠ DANE ORIENTACYJNE — TYLKO DO CELÓW SZKOLENIOWYCH I PLANISTYCZNYCH. Przed lotem transgranicznym zweryfikuj aktualne punkty w AIP VFR ENR 2.1.1 (wymaga rejestracji PANSA: ais.pansa.pl) lub na Lotniczej Mapie Polski ICAO 1:500 000.
A3: Źródło: AIP VFR ENR 2.1.1 / Lotnicza Mapa Polski ICAO (ed. 20, dane na 17 APR 2025) + opisy sektorów AIRCOM z AIP VFR ENR 2.6 via dlapilota.pl. FPL crossing point może być REP, radiolatarnia lub współrzędne geograficzne (VFR ENR 1.5 pkt 4.5). Kraje Schengen (DE, CZ, SK, LT) — brak obowiązku FPL w przestrzeni niekontrolowanej G (wg AIP VFR ENR 1.5 Uwaga 1), ale kraje te mogą wymagać własnych FPL (sprawdź!). Granice PL-BY, PL-UA, PL-RU — FPL obowiązkowy, złożyć 1h przed EOBT.
A5: # | B5: Punkt / Nazwa | C5: Granica | D5: Sąsiedni FIR | E5: Lat (decimal) | F5: Lon (decimal) | G5: Lat DMS | H5: Lon DMS | I5: Opis / Lokalizacja
A6: GRANICA ZACHODNIA — Niemcy / FIR EDWW (Berlin)
A7: W01 | B7: PIEŃSK | C7: PL-DE | D7: EDWW (Berlin) | E7: 51.2617 | F7: 14.8233 | G7: 511542N | H7: 0144924E | I7: Przejście graniczne Pieńsk/Görlitz. Zachodnia granica FIR WARSZAWA.
A8: W02 | B8: ŁĘKNICA | C8: PL-DE | D8: EDWW (Berlin) | E8: 51.54 | F8: 14.735 | G8: 513224N | H8: 0144406E | I8: Rejon m. Łęknica / Bad Muskau
A9: W03 | B9: ŚWIECKO | C9: PL-DE | D9: EDWW (Berlin) | E9: 52.3358 | F9: 14.6017 | G9: 522009N | H9: 0143606E | I9: Przejście graniczne Frankfurt/Słubice (A2/E30)
A10: W04 | B10: KOŁBASKOWO | C10: PL-DE | D10: EDWW (Berlin) | E10: 53.5283 | F10: 14.335 | G10: 533142N | H10: 0142006E | I10: Rejon Kołbaskowo k/Szczecina, granica PL-DE
A11: W05 | B11: LUBIESZYN | C11: PL-DE | D11: EDWW (Berlin) | E11: 53.6533 | F11: 14.3133 | G11: 533912N | H11: 0141848E | I11: Rejon Lubieszyn / Löcknitz
A12: GRANICA POŁUDNIOWA — Czechy / FIR LKAA (Praha)
A13: S01 | B13: GŁUCHOŁAZY | C13: PL-CZ | D13: LKAA (Praha) | E13: 50.3208 | F13: 17.3833 | G13: 501915N | H13: 0172300E | I13: Rejon Głuchołazy – przejście Mikulovice/Jarnołtówek
A14: S02 | B14: KUDOWA | C14: PL-CZ | D14: LKAA (Praha) | E14: 50.4358 | F14: 16.2383 | G14: 502609N | H14: 0161418E | I14: Rejon Kudowy-Zdroju, przejście PL-CZ
A15: S03 | B15: BOBOSZÓW | C15: PL-CZ | D15: LKAA (Praha) | E15: 50.2867 | F15: 16.8317 | G15: 501712N | H15: 0164954E | I15: Rejon Boboszów (Góry Złote / Jeseník area)
A16: S04 | B16: CIESZYN | C16: PL-CZ | D16: LKAA (Praha) | E16: 49.7483 | F16: 18.6317 | G16: 494454N | H16: 0183754E | I16: Przejście graniczne Cieszyn (PL) / Český Těšín (CZ)
A17: S05 | B17: JASTRZĘBIE | C17: PL-CZ | D17: LKAA (Praha) | E17: 49.9167 | F17: 18.55 | G17: 495500N | H17: 0183300E | I17: Zachodni narożnik południowej granicy FIR WARSZAWA, na S od Jastrzębia-Zdroju (49°55'N 018°33'E wg AIP VFR ENR sektor AIRCOM)
A18: GRANICA POŁUDNIOWA — Słowacja / FIR LZBB (Bratislava)
A19: S06 | B19: CHYŻNE | C19: PL-SK | D19: LZBB (Bratislava) | E19: 49.4692 | F19: 19.7767 | G19: 492809N | H19: 0194636E | I19: Przejście graniczne Chyżne (DK7/E77), na S od Nowego Targu
A20: S07 | B20: ŁYSA POLANA | C20: PL-SK | D20: LZBB (Bratislava) | E20: 49.2233 | F20: 20.0717 | G20: 491324N | H20: 0200418E | I20: Przejście graniczne Łysa Polana (Tatry), rejon EPNT
A21: S08 | B21: KONIECZNA | C21: PL-SK | D21: LZBB (Bratislava) | E21: 49.3633 | F21: 21.2283 | G21: 492148N | H21: 0211342E | I21: Przejście graniczne Konieczna/Becherov (Beskid Niski)
A22: S09 | B22: BARWINEK | C22: PL-SK | D22: LZBB (Bratislava) | E22: 49.36 | F22: 21.6583 | G22: 492136N | H22: 0213930E | I22: Przejście graniczne Barwinek/Vyšný Komárnik (A4/E40)
A23: GRANICA WSCHODNIA — Ukraina / FIR UKLL (Lwów) / UKWW (Kijów)
A24: E01 | B24: MEDYKA | C24: PL-UA | D24: UKLL (Lviv) | E24: 49.7875 | F24: 22.8417 | G24: 494715N | H24: 0225030E | I24: Przejście graniczne Medyka/Shehyni (A4/E40). Drogowe przejście graniczne z Ukrainą w Medyce (wg AIP VFR sektor AIRCOM F/H)
A25: E02 | B25: HREBENNE | C25: PL-UA | D25: UKLL (Lviv) | E25: 50.2933 | F25: 23.8367 | G25: 501736N | H25: 0235012E | I25: Przejście graniczne Hrebenne/Rawa Ruska
A26: E03 | B26: ZOSIN | C26: PL-UA | D26: UKWW (Kyiv) | E26: 50.7367 | F26: 24.1633 | G26: 504412N | H26: 0240948E | I26: Przejście graniczne Zosin/Ustyług (Hrubieszów area)
A27: E04 | B27: DOROHUSK | C27: PL-UA | D27: UKWW (Kyiv) | E27: 51.1883 | F27: 23.895 | G27: 511118N | H27: 0235342E | I27: Przejście graniczne Dorohusk/Jagodzin, Chełm area
A28: GRANICA WSCHODNIA — Białoruś / FIR UMMV (Mińsk)
A29: E05 | B29: TERESPOL | C29: PL-BY | D29: UMMV (Minsk) | E29: 52.0783 | F29: 23.635 | G29: 520442N | H29: 0233806E | I29: Przejście graniczne Terespol/Brest. Wschodnia granica FIR WARSZAWA (na wschód od Terespola, wg AIP VFR sektor AIRCOM F)
A30: E06 | B30: BOBROWNIKI | C30: PL-BY | D30: UMMV (Minsk) | E30: 53.265 | F30: 23.645 | G30: 531554N | H30: 0233842E | I30: Przejście graniczne Bobrowniki/Bierestovica k/Białegostoku
A31: E07 | B31: KUŹNICA | C31: PL-BY | D31: UMMV (Minsk) | E31: 53.5983 | F31: 23.6283 | G31: 533554N | H31: 0233742E | I31: Przejście graniczne Kuźnica Białostocka/Brest
A32: E08 | B32: SUWAŁKI | C32: PL-BY | D32: UMMV (Minsk) | E32: 54.105 | F32: 23.05 | G32: 540618N | H32: 0230300E | I32: Rejon Suwałki, granica PL-BY (trójstyk PL-BY-LT na S)
A33: GRANICA PÓŁNOCNO-WSCHODNIA — Litwa / FIR EYVI (Wilno)
A34: N01 | B34: OGRODNIKI | C34: PL-LT | D34: EYVI (Vilnius) | E34: 54.3533 | F34: 23.5283 | G34: 542112N | H34: 0233142E | I34: Przejście graniczne Ogrodniki/Lazdijai (droga 16/E67)
A35: N02 | B35: BUDZISKO | C35: PL-LT | D35: EYVI (Vilnius) | E35: 54.4333 | F35: 23.1117 | G35: 542600N | H35: 0230642E | I35: Przejście graniczne Budzisko (A8/Via Baltica)
A36: GRANICA PÓŁNOCNA — Kaliningrad / FIR UMKK
A37: N03 | B37: GOŁDAP | C37: PL-RU | D37: UMKK (Kaliningrad) | E37: 54.3117 | F37: 22.31 | G37: 541842N | H37: 0221836E | I37: Rejon Gołdap, granica PL-RU (Obwód Kaliningradzki)
A38: N04 | B38: GRONOWO | C38: PL-RU | D38: UMKK (Kaliningrad) | E38: 54.3317 | F38: 19.8833 | G38: 541954N | H38: 0195300E | I38: Przejście graniczne Gronowo/Mamonovo k/Elbląga
A39: N05 | B39: BEZLEDY | C39: PL-RU | D39: UMKK (Kaliningrad) | E39: 54.0617 | F39: 20.9167 | G39: 540342N | H39: 0205500E | I39: Przejście graniczne Bezledy/Bagrationovsk (DK51)
A40: GRANICA MORSKA — Bałtyk
A41: N06 | B41: KOŁOBRZEG | C41: PL morze | D41: EDMM/EDWW | E41: 54.17 | F41: 15.5367 | G41: 541012N | H41: 0153212E | I41: Wybrzeże bałtyckie – rejon Kołobrzegu, granica FIR nad morzem
...

Sheet Info
A1: Informacje o bazie danych
A3: ZAWARTOŚĆ SKOROSZYTU:
A4: • Arkusz 'Wszystkie punkty' — pełna lista punktów VFR (decimal degrees WGS-84), z filtrami
A5: • Arkusz 'DMS (format AIP)' — te same punkty w formacie ddmmssN / dddmmssE (jak w AIP Poland)
A6: • Arkusz 'Przegląd lotnisk' — lista lotnisk z ARP i liczbą punktów, suma w ostatnim wierszu
A7: • Arkusz 'Bez punktów VFR' — lotniska AD4 w AIP, dla których pilothub.pl nie wykazuje tabeli punktów
A8: • Arkusz 'Info' — ten arkusz
A10: ZAKRES — LOTNISKA KONTROLOWANE (AD 2) z punktami CTR/TMA:
A11: EPBY(10), EPGD(7), EPKK(13), EPKT(10), EPLB(10), EPLL(11), EPMO(8), EPPO(12),
A12: EPRA(10), EPRZ(10), EPSC(4), EPSY(8), EPWA(19), EPWR(6), EPZG(8)
A14: ZAKRES — LOTNISKA NIEKONTROLOWANE (AD 4) Z PUNKTAMI VFR:
A15: EPBA(3), EPBC(14), EPBK(6), EPCD(3), EPGI(5), EPGL(7), EPJG(6), EPJS(6),
... A29: Wygenerowano: 25 kwietnia 2026. Lotnisk z punktami: 55. Łącznie punktów VFR: 342.
